Workbook
Name Capacity: #REF!
Name TCapacity: #REF!

Sheet Assumptions
A1: Parameter | B1: Value | C1: unit | D1: Reference
A3: Electricity Cost | B3: 0.08 | C3: $/kWhe | D3: MSC value supplied
A4: COP Brackish | B4: 3.5 | D4: Typical HP used for cooling using air sourced HP, mfg quote
A5: COP Seawater | B5: 3.5 | D5: Typical HP with seawter cooling (liquid), mfg quote
A6: COP Produced | B6: 3.2 | D6: Typical HP used for cooling using air sourced Heat pump, HT quote
A7: Brackish Feed Salinity | B7: 2000 | C7: mg/l | D7: Typical range 2-10k
A8: Brackish brine Salinity | B8: 150000 | C8: mg/l | D8: Assumes MLD design
A9: Seawater Feed Salinity | B9: 35000 | C9: mg/l | D9: Typically 36-40k
A10: Seawater brine Salinity | B10: 100000 | C10: mg/l | D10: Assumes ocean discharge, 65% recovery
A11: Produced Water Feed | B11: 100000 | C11: mg/l | D11: Typical in Permean basin
A12: Produced Water brine | B12: 200000 | C12: mg/l | D12: Requested recovery 50%
A13: Plant Availability | B13: 98 | C13: % | D13: S/B >95%
A14: Interest Rate | B14: 6 | C14: % | D14: Project Finance rate assumption
A15: Plant Life | B15: 20 | C15: years | D15: Typical for brackish and seawater, 10yrs for oil and gas
A16: Heat Pump Capex | B16: 250 | C16: $/kWhth | D16: From table in Text, IEA Conf. Proc.
A17: FO Electricicty (MLD) | B17: 1.3 | C17: kWh/m3 | D17: From PFD Tab
A18: FO Thermal brackish& Sea | B18: 35 | C18: kWh/m3 | D18: From PFD tab
... A22: RO Electrical (O&G) | B22: 23 | C22: kWh/m3 | D22: From GWI refernce in Workbook

Sheet Seawater Report_SanDiego
A1: Variable | B1: Value | C1: Unit | D1: Reference
A2: DC Cooling Req | B2: 1 | C2: MW | D2: Design Point
A3: DC Waste Heat Avail | B3: 1.459854 | C3: MW | D3: From Quote by HP mfg.
A4: FO & RO Plant Size | B4: 1000 | C4: m3/day | D4: Based on heat avail.
A5: FO Plant CAPEX | B5: 1651720.5 | D5: Derived by Trevi
A6: FO Electrical Energy | B6: 1.3 | C6: kWh/m3 | D6: Assumption tab
A7: FO Thermal Energy | B7: 35 | C7: kWh/m3 | D7: Assumption tab
A8: COP heat Pump with FO | B8: 3.5 | D8: Calculated from lift and industry quote
A9: FO
A10: Annual Electricity cost | B10: =Assumptions!B3*B4*'Seawater Report_SanDiego'!B6*365 -> 37960 | D10: Assumption tab & Calculated
A11: Annual FO Thermal Energy Costs (No WH & DC) | B11: =W36*Assumptions!B3*1000 -> 330132.98 | D11: Calculated from San Diego Table below
A12: Annual FO Thermal Energy Costs( 30C WH) | B12: =W37*Assumptions!B3*1000 -> 290702.82 | D12: Calculated from San Diego Table below
A13: Annual FO Thermal Energy Costs (45C WH) | B13: =W49*Assumptions!B3*1000 -> 211420.23 | D13: Calculated from San Diego Table below
A14: FO CAPEX | B14: =B5 -> 1651720.5 | D14: Calculated
A15: Annual FO CAPEX Cost | B15: 42985.864 | D15: Calculated
A16: HEAT Pump CAPEX | B16: 500000 | D16: Calculated
A17: Annual HP CAPEX | B17: 42985.864 | D17: From Ref in Document
A18: Annual FO Plant OPEX Cost | B18: =B14*0.087 -> 143699.69 | D18: Calculated
A19: UHPRO
A20: Annual Electricity cost | B20: =Assumptions!B3*B4*Assumptions!B21*365 -> 166440 | D20: Assumptions tab
A21: RO CAPEX Cost | B21: 1500000 | D21: GWI databook
A22: Annual CAPEX Cost | B22: =-PMT((Assumptions!B14/100)/12,12*Assumptions!B15,B21,0)*12 -> 128957.59 | D22: Calculated
A23: Annual OPEX Cost | B23: =0.087*B21 -> 130500 | D23: GWI databook
A24: Recovery rate | B24: =(Assumptions!B10-Assumptions!B9)/Assumptions!B10 -> 0.65 | D24: Calculated
A25: LCOW FO (no DC) | B25: =((B15+B17+B11+B10+B18)/365)/1000 -> 1.6377107 | C25: /m3 | D25: =Annualized (Electricity Cost + Thermal costs (no HP)+ FO CAPEX+FO OPEX+ HeatPump CAPEX)/1000
A26: LCOW FO (+ DCWH @30 deg C) | B26: =((B15+B17+B12+B10+B18)/365)/1000 -> 1.5296828 | C26: /m3 | D26: =Annualized (Electricity Cost + Thermal costs (w HP @30 deg C)+ FO CAPEX+ OPEX+ HeatPump CAPEx)/1000
A27: LCOW FO (+ DCWH @45 degC + 33 DegC Ret) | B27: =((B15+B17+B13+$B$10+$B$18)/365)/1000 -> 1.3124703 | C27: /m3 | D27: =Annualized (Electricity Cost + Thermal costs (w HP@ 45 deg C)+ FO CAPEX+ OPEX+ HeatPump CAPEX)/1000
A28: LCOW UHPRO | B28: =((B22+B23+B20)/365)/1000 -> 1.1668427 | C28: /m3 | D28: =Annualized (RO Electricity Cost + RO CAPEX+ RO OPEX)/1000
J30: Heat Pump Savings with DC Waste heat vs sea water sourced HP ( 30C DC )
A32: Levelized Cost of Water - LCOW ($/m3) | B32: LCOW FO (No WH) | C32: LCOW (with DC WH) | D32: LCOW (with DC WH) | E32: LCOW RO | J32: Location | K32: jan | L32: feb | M32: march | N32: April | O32: may | P32: june | Q32: july | R32: Aug | S32: Sep | T32: Oct | U32: Nov | V32: Dec | W32: Annual Energy Used (MWH)
A33: Location / Temperature | B33: Ambient | C33: 30C In + 18C Out | D33: 45C In + 33C Out | E33: Ambient | J33: San Diego, CA | K33: ='COP & Temps SWFO'!C6 -> 14 | L33: ='COP & Temps SWFO'!D6 -> 14 | M33: ='COP & Temps SWFO'!E6 -> 14 | N33: ='COP & Temps SWFO'!F6 -> 15.5 | O33: ='COP & Temps SWFO'!G6 -> 16.5 | P33: ='COP & Temps SWFO'!H6 -> 18 | Q33: ='COP & Temps SWFO'!I6 -> 19 | R33: ='COP & Temps SWFO'!J6 -> 20 | ... V33: ='COP & Temps SWFO'!N6 -> 15
A34: San Diego, CA | B34: =B25 -> 1.6377107 | C34: =B26 -> 1.5296828 | D34: =B27 -> 1.3124703 | E34: =B28 -> 1.1668427 | J34: Seawater COP | K34: ='COP & Temps SWFO'!C7 -> 2.9615385 | L34: ='COP & Temps SWFO'!D7 -> 2.9615385 | M34: ='COP & Temps SWFO'!E7 -> 2.9615385 | N34: ='COP & Temps SWFO'!F7 -> 3.0314961 | O34: ='COP & Temps SWFO'!G7 -> 3.08 | P34: ='COP & Temps SWFO'!H7 -> 3.1557377 | Q34: ='COP & Temps SWFO'!I7 -> 3.2083333 | R34: ='COP & Temps SWFO'!J7 -> 3.2627119 | ... V34: ='COP & Temps SWFO'!N7 -> 3.0078125 | W34: Ref; ASHRAE, IAE, US DOE sources - see Capex and opex calcs.
J35: COP of DC waste Heat (53% of Carnot cycle (water) | K35: 3.5 | L35: 3.5 | M35: 3.5 | N35: 3.5 | O35: 3.5 | P35: 3.5 | Q35: 3.5 | R35: 3.5 | S35: 3.5 | T35: 3.5 | U35: 3.5 | V35: 3.5 | W35: Mfg data
J36: FO Energy No DC WH | K36: =($B$3/K34)*31*24 -> 366.74566 | L36: =($B$3/L34)*28*24 -> 331.25415 | M36: =($B$3/M34)*31*24 -> 366.74566 | N36: =($B$3/N34)*30*24 -> 346.72481 | O36: =($B$3/O34)*31*24 -> 352.64006 | P36: =($B$3/P34)*30*24 -> 333.07423 | Q36: =($B$3/Q34)*30*24 -> 327.61399 | R36: =($B$3/R34)*30*24 -> 322.15376 | S36: =($B$3/S34)*30*24 -> 327.61399 | T36: =($B$3/T34)*31*24 -> 346.99782 | U36: =($B$3/U34)*30*24 -> 343.99469 | V36: =($B$3/V34)*31*24 -> 361.10342 | W36: =SUM(K36:V36) -> 4126.6622
J37: FO Energy w DC 30 deg C | K37: =($B$3/K35)*31*24 -> 310.32325 | L37: =($B$3/L35)*28*24 -> 280.29197 | M37: =($B$3/M35)*31*24 -> 310.32325 | N37: =($B$3/N35)*30*24 -> 300.31283 | O37: =($B$3/O35)*31*24 -> 310.32325 | P37: =($B$3/P35)*30*24 -> 300.31283 | Q37: =($B$3/Q35)*30*24 -> 300.31283 | R37: =($B$3/R35)*30*24 -> 300.31283 | S37: =($B$3/S35)*30*24 -> 300.31283 | T37: =($B$3/T35)*31*24 -> 310.32325 | U37: =($B$3/U35)*30*24 -> 300.31283 | V37: =($B$3/V35)*31*24 -> 310.32325 | W37: =SUM(K37:V37) -> 3633.7852
J42: Heat Pump Savings with DC Waste heat vs seawater sourced HP (45C DC )
P43: #VALUE!
K44: Location | L44: jan | M44: feb | N44: march | O44: April | P44: may | Q44: june | R44: july | S44: Aug | T44: Sep | U44: Oct | V44: Nov | W44: Dec | X44: Annual Energy Used (MWH)
J45: San Diego, CA | K45: ='COP & Temps SWFO'!C6 -> 14 | L45: ='COP & Temps SWFO'!D6 -> 14 | M45: ='COP & Temps SWFO'!E6 -> 14 | N45: ='COP & Temps SWFO'!F6 -> 15.5 | O45: ='COP & Temps SWFO'!G6 -> 16.5 | P45: ='COP & Temps SWFO'!H6 -> 18 | Q45: ='COP & Temps SWFO'!I6 -> 19 | R45: ='COP & Temps SWFO'!J6 -> 20 | ... V45: ='COP & Temps SWFO'!N6 -> 15
J46: Sea Water HP COP | K46: ='COP & Temps SWFO'!C7 -> 2.9615385 | L46: ='COP & Temps SWFO'!D7 -> 2.9615385 | M46: ='COP & Temps SWFO'!E7 -> 2.9615385 | N46: ='COP & Temps SWFO'!F7 -> 3.0314961 | O46: ='COP & Temps SWFO'!G7 -> 3.08 | P46: ='COP & Temps SWFO'!H7 -> 3.1557377 | Q46: ='COP & Temps SWFO'!I7 -> 3.2083333 | R46: ='COP & Temps SWFO'!J7 -> 3.2627119 | ... V46: ='COP & Temps SWFO'!N7 -> 3.0078125 | W46: Ref; ASHRAE, IAE, US DOE sources - see Capex and opex calcs.
...

Sheet COP & Temps SWFO
A2: Location Data - Monthly Average Seawater Temperature and COP calculations
B4: Location | C4: Jan | D4: Feb | E4: Mar | F4: April | G4: May | H4: Jun | I4: Jul | J4: Aug | K4: Sept | L4: Oct | M4: Nov | N4: Dec
B6: San Diego, CA | C6: 14 | D6: 14 | E6: 14 | F6: 15.5 | G6: 16.5 | H6: 18 | I6: 19 | J6: 20 | K6: 19 | L6: 17.5 | M6: 16 | N6: 15 | P6: Average Seawater temperature
B7: HP COP* | C7: =((352)/(352-(273+C6))/6.4)*$M$23 -> 2.9615385 | D7: =((352)/(352-(273+D6))/6.4)*$M$23 -> 2.9615385 | E7: =((352)/(352-(273+E6))/6.4)*$M$23 -> 2.9615385 | F7: =((352)/(352-(273+F6))/6.4)*$M$23 -> 3.0314961 | G7: =((352)/(352-(273+G6))/6.4)*$M$23 -> 3.08 | H7: =((352)/(352-(273+H6))/6.4)*$M$23 -> 3.1557377 | I7: =((352)/(352-(273+I6))/6.4)*$M$23 -> 3.2083333 | J7: =((352)/(352-(273+J6))/6.4)*$M$23 -> 3.2627119 | ... N7: =((352)/(352-(273+N6))/6.4)*$M$23 -> 3.0078125 | P7: calculated COP for 30C heat
B8: Miami, Fl | C8: 24 | D8: 24 | E8: 24.6 | F8: 25.6 | G8: 26.9 | H8: 28.5 | I8: 29.5 | J8: 29.9 | K8: 29.4 | L8: 28.2 | M8: 26.5 | N8: 25.3
B9: HP COP* | C9: =((352)/(352-(273+C8))/6.4)*$M$23 -> 3.5 | D9: =((352)/(352-(273+D8))/6.4)*$M$23 -> 3.5 | E9: =((352)/(352-(273+E8))/6.4)*$M$23 -> 3.5386029 | F9: =((352)/(352-(273+F8))/6.4)*$M$23 -> 3.6048689 | G9: =((352)/(352-(273+G8))/6.4)*$M$23 -> 3.6948177 | H9: =((352)/(352-(273+H8))/6.4)*$M$23 -> 3.8118812 | I9: =((352)/(352-(273+I8))/6.4)*$M$23 -> 3.8888889 | J9: =((352)/(352-(273+J8))/6.4)*$M$23 -> 3.9205703 | ... N9: =((352)/(352-(273+N8))/6.4)*$M$23 -> 3.58473
B10: Corpus Christi, TX | C10: 17.2 | D10: 16.7 | E10: 18.9 | F10: 22.8 | G10: 26.1 | H10: 28.9 | I10: 30 | J10: 30 | K10: 29.4 | L10: 26.1 | M10: 22.2 | N10: 19.4
B11: HP COP* | C11: =((352)/(352-(273+C10))/6.4)*$M$23 -> 3.1148867 | D11: =((352)/(352-(273+D10))/6.4)*$M$23 -> 3.0898876 | E11: =((352)/(352-(273+E10))/6.4)*$M$23 -> 3.202995 | F11: =((352)/(352-(273+F10))/6.4)*$M$23 -> 3.4252669 | G11: =((352)/(352-(273+G10))/6.4)*$M$23 -> 3.6389414 | H11: =((352)/(352-(273+H10))/6.4)*$M$23 -> 3.8423154 | I11: =((352)/(352-(273+I10))/6.4)*$M$23 -> 3.9285714 | J11: =((352)/(352-(273+J10))/6.4)*$M$23 -> 3.9285714 | ... N11: =((352)/(352-(273+N10))/6.4)*$M$23 -> 3.2298658
B12: Virginia Beach, VA | C12: 7.5 | D12: 5.2 | E12: 7 | F12: 11.8 | G12: 17.3 | H12: 22.7 | I12: 25.6 | J12: 25.9 | K12: 24.2 | L12: 20.1 | M12: 14.4 | N12: 9.9
B13: HP COP* | C13: =((352)/(352-(273+C12))/6.4)*$M$23 -> 2.6923077 | D13: =((352)/(352-(273+D12))/6.4)*$M$23 -> 2.6084011 | E13: =((352)/(352-(273+E12))/6.4)*$M$23 -> 2.6736111 | F13: =((352)/(352-(273+F12))/6.4)*$M$23 -> 2.8645833 | G13: =((352)/(352-(273+G12))/6.4)*$M$23 -> 3.1199352 | H13: =((352)/(352-(273+H12))/6.4)*$M$23 -> 3.4191829 | I13: =((352)/(352-(273+I12))/6.4)*$M$23 -> 3.6048689 | J13: =((352)/(352-(273+J12))/6.4)*$M$23 -> 3.6252354 | ... N13: =((352)/(352-(273+N12))/6.4)*$M$23 -> 2.7858177
B14: Honolulu, HI | C14: 24.7 | D14: 24.4 | E14: 24.3 | F14: 25 | G14: 25.5 | H14: 25.9 | I14: 26 | J14: 26.4 | K14: 26.9 | L14: 26.5 | M14: 25.9 | N14: 25
B15: HP COP* | C15: =((352)/(352-(273+C14))/6.4)*$M$23 -> 3.5451197 | D15: =((352)/(352-(273+D14))/6.4)*$M$23 -> 3.525641 | E15: =((352)/(352-(273+E14))/6.4)*$M$23 -> 3.5191956 | F15: =((352)/(352-(273+F14))/6.4)*$M$23 -> 3.5648148 | G15: =((352)/(352-(273+G14))/6.4)*$M$23 -> 3.5981308 | H15: =((352)/(352-(273+H14))/6.4)*$M$23 -> 3.6252354 | I15: =((352)/(352-(273+I14))/6.4)*$M$23 -> 3.6320755 | J15: =((352)/(352-(273+J14))/6.4)*$M$23 -> 3.6596958 | ... N15: =((352)/(352-(273+N14))/6.4)*$M$23 -> 3.5648148
B18: calculations:
B20: * COP calculated is ratio of COP (actual)/COP (datacenter)* COP of manufacturer: COP = Thot/(Thot-Tcold) (actual) / COP (datacenter) * COP manufacturer
B21: * ASHRAE D-CCC23-21.pdf
B22: Data Center Ideal Carnot COP @ 30C:
B23: (273+ 79)/((273+79)- (273+24)) = 6.4 | F23: 79C = Avg Hot and 24C = Avg Cold @30C DC | J23: (30C+18C)/2=24C | L23: COP @30C | M23: =Assumptions!B5 -> 3.5
B24: Data Center Ideal Carnot COP @ 45C: | L24: COP @45C | M24: =(8.8/6.4)*M23 -> 4.8125
B25: (273+ 79)/((273+79)- (273+39)) = 8.8 | F25: 79C = Avg Hot and 31.5C = Avg Cold @45C DC | J25: (45C+33C)/2 = 39C
B27: Data Center Ambient Seawater COP
B28: (273+79)/((273+79)-(273+T)) | F28: Use to calculate ambient seawater COP
B29: 352/(352-(273+T))
B30: Actual COP is then:: COP(mfg)* COPambient (ideal carnot)/COP DC i(deal carnot)
