Workbook
Name Capacity: #REF!
Name TCapacity: #REF!

Sheet Assumptions
A1: Parameter | B1: Value | C1: unit | D1: Reference
A3: Electricity Cost | B3: 0.08 | C3: $/kWhe | D3: MSC value supplied
A4: COP Brackish | B4: 3.5 | D4: Typical HP used for cooling using air sourced HP, mfg quote
A5: COP Seawater | B5: 3.5 | D5: Typical HP with seawter cooling (liquid), mfg quote
A6: COP Produced | B6: 3.3 | D6: Typical HP used for cooling using air sourced Heat pump, HT quote
A7: Brackish Feed Salinity | B7: 2000 | C7: mg/l | D7: Typical range 2-10k
A8: Brackish brine Salinity | B8: 150000 | C8: mg/l | D8: Assumes MLD design
A9: Seawater Feed Salinity | B9: 36000 | C9: mg/l | D9: Typically 36-40k
A10: Seawater brine Salinity | B10: 100000 | C10: mg/l | D10: Assumes ocean discharge, 65% recovery
A11: Produced Water Feed | B11: 100000 | C11: mg/l | D11: Typical in Permean basin
A12: Produced Water brine | B12: 200000 | C12: mg/l | D12: Requested recovery 50%
A13: Plant Availability | B13: 98 | C13: % | D13: S/B >95%
A14: Water Sell price brackish | B14: 2.89 | C14: $/m3 | D14: Set by market, used for average baseline, see table below
A15: Water Sell price Seawater | B15: 0.8 | C15: $/m3 | D15: Set by market, used for baseline average, see table below
A16: Water Sell price Produced | B16: 6 | C16: $/m3 | D16: Set by market, used for baseline refernce, see table below
A17: Interest Rate | B17: 6 | C17: % | D17: Project Finance rate assumption
A18: Plant Life | B18: 20 | C18: years | D18: Typical for brackish and seawater, 10yrs for oil and gas
... A25: UPRO Electrical (Sea) | B25: 5.7 | C25: kWh/m3 | D25: From GWI reference in Workbook
A26: UPRO&MVR Electrical (O&G) | B26: =B25+23 -> 28.7 | C26: kWh/m3 | D26: From GWI reference in Workbook
A29: City | B29: Water Source | C29: Estimated Lowest Tier Cost (USD/m³)
A30: Phoenix, AZ | B30: Surface & Groundwater | C30: 1.96
A31: El Paso, TX | B31: Brackish Groundwater (Desal.) | C31: 5.43
A32: Midland, TX | B32: Groundwater | C32: 2.99
A33: Albuquerque, NM | B33: Surface & Groundwater | C33: 1.49
A34: Reno, NV | B34: Surface Water | C34: 1.79 | E34: The average multiplier that cities charge consumers over the estimated Levelized Cost of Water (LCOW) from brackish desalination (assumed at $0.50/m³) is approximately 5.78×.
A35: Sonoma, CA | B35: Surface Water | C35: 1.7
A36: Fresno, CA (est.) | B36: Surface & Groundwater | C36: 2.5 | E36: You can explore the detailed comparison in the table provided, which includes each city’s markup over the base LCOW. Let me know if you'd like the same analysis using seawater desalination LCOW or for higher usage tiers.
A37: San Francisco, CA | B37: Surface Water | C37: 8.2
A38: Monterey, CA | B38: Surface & Groundwater | C38: 5.29
A39: San Angelo, TX | B39: Brackish Groundwater (Desal.) | C39: 1.98
A40: Alamogordo, NM | B40: Brackish Groundwater (Desal.) | C40: 1.98
A41: Odessa, TX | B41: Brackish Groundwater (Desal.) | C41: 1.98
A42: San Antonio, TX | B42: Brackish Groundwater (Desal.) | C42: 2
A43: Los Angeles, CA | B43: Brackish & Surface Water | C43: 3
A44: Oxnard, CA | B44: Brackish Groundwater (Desal.) | C44: 2.5
A45: Tampa, FL | B45: Brackish & Surface Water | C45: 2.2
A46: Jacksonville, FL | B46: Brackish & Surface Water | C46: 2.1
B48: Average | C48: =SUM(C30:C46)/17 -> 2.8876471
A50: City | B50: Seawater | C50: Est lowest Tier (USD/m3)
A51: San Diego | B51: Seawater
...

Sheet Produced
A1: Variable | B1: Value | C1: Unit | D1: Reference
A2: DC Cooling Req | B2: 1 | C2: MW | D2: Design Point
A3: DC Waste Heat Avail | B3: =B2/0.685 -> 1.459854 | C3: MW | D3: From Quote by HP mfg.
A4: FO & RO Plant Size | B4: =(B3*1000*24)/B7 -> 700.72993 | C4: m3/day | D4: Based on heat avail.
A5: FO Plant CAPEX | B5: 2557664.2 | D5: Derived by Trevi
A6: FO Electrical Energy | B6: =Assumptions!B21 -> 4.5 | C6: kWh/m3 | D6: Assumption tab
A7: FO Thermal Energy | B7: =Assumptions!B23 -> 50 | C7: kWh/m3 | D7: Assumption tab
A8: COP heat Pump with FO | B8: =Assumptions!B6 -> 3.3 | D8: Calculated from lift and industry quote
A9: FO
A10: Annual Electricity cost | B10: =Assumptions!B3*B4*B6*365 -> 92075.912 | D10: Assumption tab & Calculated
A11: Annual FO Thermal Energy Costs (No WH & DC) | B11: =X39*Assumptions!B3*1000 -> 328837.3 | D11: Calculated from Dallas Table below
A12: Annual FO Thermal Energy Costs( 30C WH) | B12: =X40*Assumptions!B3*1000 -> 308321.17 | D12: Calculated from Dallas Table below
A13: Annual FO Thermal Energy Costs (45C WH) | B13: =X48*Assumptions!B3*1000 -> 231240.88 | D13: Calculated from Dallas Table below
A14: FO CAPEX | B14: 2557664.2 | D14: Calculated
A15: Annual FO CAPEX Cost | B15: =-PMT((Assumptions!B17/100)/12,12*Assumptions!B18,B14,0)*12 -> 219886.81 | D15: Calculated
A16: HEAT Pump CAPEX | B16: =2*Assumptions!B19*B2*1000 -> 500000 | D16: Calculated
A17: Annual HP CAPEX | B17: =-PMT((Assumptions!B17/100)/12,12*Assumptions!B18,B16,0)*12 -> 42985.864 | D17: From Ref in Document
A18: Annual FO Plant OPEX Cost | B18: =0.100278*B14 -> 256477.45 | D18: Calculated
A19: UPRO+MVR
A20: Annual Electricity cost | B20: =Assumptions!B3*B4*Assumptions!B26*365 -> 587239.71 | D20: Assumptions tab
A21: RO CAPEX Cost | B21: 2732846.7 | D21: GWI databook
A22: Annual CAPEX Cost | B22: =-PMT((Assumptions!B17/100)/12,12*Assumptions!B18,B21,0)*12 -> 234947.55 | D22: Calculated
A23: Annual OPEX Cost | B23: =0.12*B21 -> 327941.61 | D23: GWI databook
A24: Recovery rate | B24: =(Assumptions!B12-Assumptions!B11)/Assumptions!B12 -> 0.5 | D24: Calculated
A25: For Dallas
A26: LCOW FO (no DC) | B26: =((B15+B17+B11+B10+B18)/365)/B4 -> 3.6762579 | D26: =Annualized (Electricity Cost + Thermal costs (no HP)+ FO CAPEX+FO OPEX+ HeatPump CAPEX)/1000
A27: LCOW FO (+ DCWH @30 deg C) | B27: =((B15+B17+B12+B10+B18)/365)/B4 -> 3.5960436 | D27: =Annualized (Electricity Cost + Thermal costs (w HP @30 deg C)+ FO CAPEX+ OPEX+ HeatPump CAPEx)/1000
A28: LCOW FO (+ DCWH @45 degC + 33 DegC Ret) | B28: =((B15+B17+B13+$B$10+$B$18)/365)/B4 -> 3.2946737 | D28: =Annualized (Electricity Cost + Thermal costs (w HP@ 45 deg C)+ FO CAPEX+ OPEX+ HeatPump CAPEX)/1000
A29: LCOW UHPRO | B29: =((B22+B23+B20)/365)/B4 -> 4.4967938 | D29: =Annualized (RO Electricity Cost + RO CAPEX+ RO OPEX)/1000
A33: =K36 -> Dallas | B33: With 30C DC Heat | C33: $/m3 | D33: $/bbl | E33: With 45C DC Heat | F33: $/m3 | G33: $/bbl | K33: Heat Pump Savings with DC Waste heat vs Produced water sourced HP ( 30C DC )
B34: LCOW FO (no DC) | C34: =($B$10+$B$38+$B$15+$B$17+$B$18)/($B$4*365) -> 3.6762579 | D34: =C34/6.2 -> 0.59294483 | E34: LCOW FO (no DC) | F34: =($B$10+$B$39+$B$15+$B$17+$B$18)/($B$4*365) -> 3.5960436 | G34: =F34/6.2 -> 0.58000703
B35: LCOW FO (+ DC) | C35: =($B$10+$B$12+$B$15+$B$17+$B$18)/($B$4*365) -> 3.5960436 | D35: =C35/6.2 -> 0.58000703 | E35: LCOW FO (+ DC) | F35: =($B$10+$B$13+$B$15+$B$17+$B$18)/($B$4*365) -> 3.2946737 | G35: =F35/6.2 -> 0.53139899 | K35: Location | L35: jan | M35: feb | N35: march | O35: April | P35: may | Q35: june | R35: july | S35: Aug | T35: Sep | U35: Oct | V35: Nov | W35: Dec | X35: Annual Energy Used (MWH)
B36: LCOW UPRO+MVR | C36: =($B$20+$B$22+$B$23)/($B$4*365) -> 4.4967938 | D36: =C36/6.2 -> 0.72528932 | E36: LCOW UPRO+MVR | F36: =($B$20+$B$22+$B$23)/($B$4*365) -> 4.4967938 | G36: =F36/6.2 -> 0.72528932 | K36: ='CAPEX & Opex produced'!B6 -> Dallas | L36: ='CAPEX & Opex produced'!C6 -> 8.6 | M36: ='CAPEX & Opex produced'!D6 -> 10.3 | N36: ='CAPEX & Opex produced'!E6 -> 14.6 | O36: ='CAPEX & Opex produced'!F6 -> 18.7 | P36: ='CAPEX & Opex produced'!G6 -> 23.3 | Q36: ='CAPEX & Opex produced'!H6 -> 27.8 | R36: ='CAPEX & Opex produced'!I6 -> 30.3 | ... W36: ='CAPEX & Opex produced'!N6 -> 9
K37: Ambient HP COP | L37: ='CAPEX & Opex produced'!C7 -> 2.6756757 | M37: ='CAPEX & Opex produced'!D7 -> 2.7327478 | N37: ='CAPEX & Opex produced'!E7 -> 2.8885942 | O37: ='CAPEX & Opex produced'!F7 -> 3.0546985 | P37: ='CAPEX & Opex produced'!G7 -> 3.2653673 | Q37: ='CAPEX & Opex produced'!H7 -> 3.5016077 | R37: ='CAPEX & Opex produced'!I7 -> 3.6482412 | S37: ='CAPEX & Opex produced'!J7 -> 3.6482412 | ... W37: ='CAPEX & Opex produced'!N7 -> 2.6888889 | X37: Ref; ASHRAE, IAE, US DOE sources
A38: Annual Thermal FO No DC | B38: =X39*Assumptions!B3*1000 -> 328837.3 | K38: COP of DC waste Heat (53% of Carnot cycle (air) | L38: ='CAPEX & Opex produced'!$M$18 -> 3.3 | M38: ='CAPEX & Opex produced'!$M$18 -> 3.3 | N38: ='CAPEX & Opex produced'!$M$18 -> 3.3 | O38: ='CAPEX & Opex produced'!$M$18 -> 3.3 | P38: ='CAPEX & Opex produced'!$M$18 -> 3.3 | Q38: ='CAPEX & Opex produced'!$M$18 -> 3.3 | R38: ='CAPEX & Opex produced'!$M$18 -> 3.3 | S38: ='CAPEX & Opex produced'!$M$18 -> 3.3 | ... W38: ='CAPEX & Opex produced'!$M$18 -> 3.3 | X38: Mfg data
A39: Annual Thermal 30 Deg | B39: =X40*Assumptions!B3*1000 -> 308321.17 | D39: Table right 30C | K39: FO Energy No DC WH | L39: =($B$3/L37)*31*24 -> 405.92789 | M39: =($B$3/M37)*28*24 -> 358.98735 | N39: =($B$3/N37)*31*24 -> 376.00692 | O39: =($B$3/O37)*30*24 -> 344.09121 | P39: =($B$3/P37)*31*24 -> 332.6215 | Q39: =($B$3/Q37)*30*24 -> 300.17494 | R39: =($B$3/R37)*30*24 -> 288.11003 | S39: =($B$3/S37)*30*24 -> 288.11003 | T39: =($B$3/T37)*30*24 -> 304.51831 | U39: =($B$3/U37)*31*24 -> 344.58989 | V39: =($B$3/V37)*30*24 -> 363.39507 | W39: =($B$3/W37)*31*24 -> 403.93316 | X39: =SUM(L39:W39) -> 4110.4663
A40: Annual Thermal 45 | B40: =X48*Assumptions!B3*1000 -> 231240.88 | D40: Table right 45C | K40: FO Energy w DC 30 deg C | L40: =($B$3/L38)*31*24 -> 329.13072 | M40: =($B$3/M38)*28*24 -> 297.27936 | N40: =($B$3/N38)*31*24 -> 329.13072 | O40: =($B$3/O38)*30*24 -> 318.5136 | P40: =($B$3/P38)*31*24 -> 329.13072 | Q40: =($B$3/Q38)*30*24 -> 318.5136 | R40: =($B$3/R38)*30*24 -> 318.5136 | S40: =($B$3/S38)*30*24 -> 318.5136 | T40: =($B$3/T38)*30*24 -> 318.5136 | U40: =($B$3/U38)*31*24 -> 329.13072 | V40: =($B$3/V38)*30*24 -> 318.5136 | W40: =($B$3/W38)*31*24 -> 329.13072 | X40: =SUM(L40:W40) -> 3854.0146
K41: Heat Pump Savings with DC Waste heat vs Produced sourced HP (45C DC )
P42: #VALUE!
K43: Location | L43: jan | M43: feb | N43: march | O43: April | P43: may | Q43: june | R43: july | S43: Aug | T43: Sep | U43: Oct | V43: Nov | W43: Dec | X43: Annual Energy Used (MWH)
...

Sheet CAPEX & Opex produced
B2: Location Data - Monthly Average Ambient Temperature and COP calculations
B4: Location | C4: Jan | D4: Feb | E4: Mar | F4: April | G4: May | H4: Jun | I4: Jul | J4: Aug | K4: Sept | L4: Oct | M4: Nov | N4: Dec
B6: Dallas | C6: 8.6 | D6: 10.3 | E6: 14.6 | F6: 18.7 | G6: 23.3 | H6: 27.8 | I6: 30.3 | J6: 30.3 | K6: 26.9 | L6: 20.9 | M6: 14.7 | N6: 9
B7: HP COP* | C7: =((363)/(363-(273+C6))/$B$18)*$M$18 -> 2.6756757 | D7: =((363)/(363-(273+D6))/$B$18)*$M$18 -> 2.7327478 | E7: =((363)/(363-(273+E6))/$B$18)*$M$18 -> 2.8885942 | F7: =((363)/(363-(273+F6))/$B$18)*$M$18 -> 3.0546985 | G7: =((363)/(363-(273+G6))/$B$18)*$M$18 -> 3.2653673 | H7: =((363)/(363-(273+H6))/$B$18)*$M$18 -> 3.5016077 | I7: =((363)/(363-(273+I6))/$B$18)*$M$18 -> 3.6482412 | J7: =((363)/(363-(273+J6))/$B$18)*$M$18 -> 3.6482412 | ... N7: =((363)/(363-(273+N6))/$B$18)*$M$18 -> 2.6888889
B8: Houston | C8: 11.7 | D8: 13.1 | E8: 17.2 | F8: 21.3 | G8: 25.5 | H8: 28.8 | I8: 30.5 | J8: 30.7 | K8: 28 | L8: 23.1 | M8: 17.3 | N8: 12.6
B9: HP COP* | C9: =((363)/(363-(273+C8))/$B$18)*$M$18 -> 2.7816092 | D9: =((363)/(363-(273+D8))/$B$18)*$M$18 -> 2.8322497 | E9: =((363)/(363-(273+E8))/$B$18)*$M$18 -> 2.9917582 | F9: =((363)/(363-(273+F8))/$B$18)*$M$18 -> 3.1703057 | G9: =((363)/(363-(273+G8))/$B$18)*$M$18 -> 3.3767442 | H9: =((363)/(363-(273+H8))/$B$18)*$M$18 -> 3.5588235 | I9: =((363)/(363-(273+I8))/$B$18)*$M$18 -> 3.6605042 | J9: =((363)/(363-(273+J8))/$B$18)*$M$18 -> 3.6728499 | ... N9: =((363)/(363-(273+N8))/$B$18)*$M$18 -> 2.8139535
B10: Denver | C10: -1 | D10: 1.1 | E10: 5.3 | F10: 9.9 | G10: 14.1 | H10: 20.1 | I10: 23.4 | J10: 22.6 | K10: 17.8 | L10: 11.8 | M10: 4.4 | N10: -0.8
B11: HP COP* | C11: =((363)/(363-(273+C10))/$B$18)*$M$18 -> 2.3934066 | D11: =((363)/(363-(273+D10))/$B$18)*$M$18 -> 2.4499438 | E11: =((363)/(363-(273+E10))/$B$18)*$M$18 -> 2.5714286 | F11: =((363)/(363-(273+F10))/$B$18)*$M$18 -> 2.7191011 | G11: =((363)/(363-(273+G10))/$B$18)*$M$18 -> 2.8695652 | H11: =((363)/(363-(273+H10))/$B$18)*$M$18 -> 3.1158798 | I11: =((363)/(363-(273+I10))/$B$18)*$M$18 -> 3.2702703 | J11: =((363)/(363-(273+J10))/$B$18)*$M$18 -> 3.231454 | ... N11: =((363)/(363-(273+N10))/$B$18)*$M$18 -> 2.3986784
B13: calculations:
B15: * COP calculated is ratio of COP (actual)/COP (datacenter)* COP of manufacturer: COP = Thot/(Thot-Tcold) (actual) / COP (datacenter) * COP manufacturer
B16: * ASHRAE D-CCC23-21.pdf
B17: Data Center Ideal Carnot COP @ 30C:
B18: =(273+ 90)/((273+90)- (273+24)) -> 5.5 | F18: 90C = Avg Hot of FO and 24C = Avg Cold @30C DC | J18: (30C+18C)/2=24C | L18: COP @30C | M18: =Assumptions!B6 -> 3.3
B19: Data Center Ideal Carnot COP @ 45C: | L19: COP @45C | M19: 4.4
B20: =(273+ 90)/((273+90)- (273+39)) -> 7.1176471 | F20: 90C = Avg Hot of FO and 31.5C = Avg Cold @45C DC | J20: (45C+33C)/2 = 39C
B22: Data Center Ambient COP
B23: (273+90)/((273+90)-(273+T)) | F23: Use to calculate ambient produced water COP
B24: 363/(363-(273+T))
B25: Actual COP is then:: COP(mfg)* COPambient (ideal carnot)/COP DC i(deal carnot)
B28: Location | C28: Jan | D28: Feb | E28: Mar | F28: April | G28: May | H28: Jun | I28: Jul | J28: Aug | K28: Sept | L28: Oct | M28: Nov | N28: Dec
B30: Abu Dhabi | C30: 21.5 | D30: 22.3 | E30: 25.3 | F30: 29.6 | G30: 33.7 | H30: 35.8 | I30: 37.4 | J30: 37.3 | K30: 35.5 | L30: 31.9 | M30: 27.4 | N30: 23.4
B31: HP COP* | C31: =((363)/(363-(273+C30))/$B$41)*$M$41 -> 3.179562 | D31: =((363)/(363-(273+D30))/$B$41)*$M$41 -> 3.2171344 | E31: =((363)/(363-(273+E30))/$B$41)*$M$41 -> 3.366306 | F31: =((363)/(363-(273+F30))/$B$41)*$M$41 -> 3.6059603 | G31: =((363)/(363-(273+G30))/$B$41)*$M$41 -> 3.8685613 | H31: =((363)/(363-(273+H30))/$B$41)*$M$41 -> 4.0184502 | I31: =((363)/(363-(273+I30))/$B$41)*$M$41 -> 4.1406844 | J31: =((363)/(363-(273+J30))/$B$41)*$M$41 -> 4.1328273 | ... N31: =((363)/(363-(273+N30))/$B$41)*$M$41 -> 3.2702703
B32: Riyadh | C32: 14 | D32: 16.4 | E32: 20.2 | F32: 25.2 | G32: 30.2 | H32: 33.6 | I32: 35.6 | J32: 35.3 | K32: 32.4 | L32: 27.3 | M32: 21.4 | N32: 16
B33: HP COP* | C33: =((363)/(363-(273+C32))/$B$41)*$M$41 -> 2.8657895 | D33: =((363)/(363-(273+D32))/$B$41)*$M$41 -> 2.9592391 | E33: =((363)/(363-(273+E32))/$B$41)*$M$41 -> 3.1203438 | F33: =((363)/(363-(273+F32))/$B$41)*$M$41 -> 3.3611111 | G33: =((363)/(363-(273+G32))/$B$41)*$M$41 -> 3.6421405 | H33: =((363)/(363-(273+H32))/$B$41)*$M$41 -> 3.8617021 | I33: =((363)/(363-(273+I32))/$B$41)*$M$41 -> 4.0036765 | J33: =((363)/(363-(273+J32))/$B$41)*$M$41 -> 3.9817185 | ... N33: =((363)/(363-(273+N32))/$B$41)*$M$41 -> 2.9432432
B34: muscat | C34: 22.4 | D34: 23.7 | E34: 26.9 | F34: 31.4 | G34: 35.6 | H34: 36.8 | I34: 36.4 | J34: 35.1 | K34: 34.1 | L34: 31.6 | M34: 26.9 | N34: 23.4
B35: HP COP* | C35: =((363)/(363-(273+C34))/$B$41)*$M$41 -> 3.2218935 | D35: =((363)/(363-(273+D34))/$B$41)*$M$41 -> 3.2850679 | E35: =((363)/(363-(273+E34))/$B$41)*$M$41 -> 3.451664 | F35: =((363)/(363-(273+F34))/$B$41)*$M$41 -> 3.7167235 | G35: =((363)/(363-(273+G34))/$B$41)*$M$41 -> 4.0036765 | H35: =((363)/(363-(273+H34))/$B$41)*$M$41 -> 4.093985 | I35: =((363)/(363-(273+I34))/$B$41)*$M$41 -> 4.0634328 | J35: =((363)/(363-(273+J34))/$B$41)*$M$41 -> 3.9672131 | ... N35: =((363)/(363-(273+N34))/$B$41)*$M$41 -> 3.2702703
B36: calculations:
B38: * COP calculated is ratio of COP (actual)/COP (datacenter)* COP of manufacturer: COP = Thot/(Thot-Tcold) (actual) / COP (datacenter) * COP manufacturer
B39: * ASHRAE D-CCC23-21.pdf
B40: Data Center Ideal Carnot COP @ 30C:
B41: =(273+ 90)/((273+90)- (273+24)) -> 5.5 | F41: 90C = Avg Hot of FO and 24C = Avg Cold @30C DC | J41: (30C+18C)/2=24C | L41: COP @30C | M41: 3.3
B42: Data Center Ideal Carnot COP @ 45C: | L42: COP @45C | M42: 4.4
B43: =(273+ 90)/((273+90)- (273+39)) -> 7.1176471 | F43: 90C = Avg Hot of FO and 31.5C = Avg Cold @45C DC | J43: (45C+33C)/2 = 39C
F44: Hot side = 95 & return = 85 = 90 deg C average
B45: Data Center Ambient COP
B46: (273+90)/((273+90)-(273+T)) | F46: Use to calculate ambient produced water COP
B47: 363/(363-(273+T))
