Workbook

Sheet Introduction
A2: Introduction
A4: This Excel document shows calculations for heat reuse scenarios.
A5: Large offtakers in the F&B sector often operate at approximately 8 MW.
A6: Hence, that range is what these figures are adapted to.
A8: It should be noted that there is a major scaling factor in heat reuse, for piping, but also for offtaker's configuration and OPEX costs.
A9: In other words, should even bigger offtaker needs be identified, then that would decrease costs per MW.
A10: Also note that power costs vary substantially, so they need to be checked when estimating true project costs.
A12: For the identified use cases, the figures used are found in the table below. Greyed out cells are not used in the calculations.
A13: On the next tab, those numbers are used for the calculations, and a dropdown menu (at cell H1) automatically inserts the values from the tables.
A15: The third tab shows the estimated gains for the DC heat exchange room.
A16: The costs and gains are made up of avoided infrastructure, new needed infrastructure, fuel cost avoidance, and governmental incentives.
A17: The client pointed out that in many cases, there is already cooling infrastructure in place, so in those cases, "avoidance" would be zero.
... A28: Petter Terenius for DGA, August 2025
A31: Location | B31: F&B Facility Type | C31: Distance (m) | D31: 1 MWh Electricity (€) | F31: 1 MWh Natural gas (€) | H31: Carbon Tax per MWh (€) | I31: Carbon Tax/Subsidy Comment | J31: Total Carbon Cost | K31: CAPEX Subsidies / Green Financing | L31: CAPEX Subsidies / Green Financing Comment | M31: OPEX subsidy / ton avoided carbon (€) | N31: OPEX subsidy… Comment | O31: DC Temp (°C) | P31: Offtaker Temp (°C) | Q31: Heat need Total / Heat need DC (MW) | R31: Payback period comment
A32: European average | B32: F&B industry | C32: 1000 | D32: 150 | E32: Electricity prices vary widely: must be investigated by actual case. | F32: 54 | G32: Cheaper per MWh, but carbon taxes and volatility make it less attractive. | H32: 12 | I32: EU ETS only applies to industries over 20 MW; thus it does not pertain to the use cases. | J32: =SUM(F32+H32) -> 66 | K32: 0.3 | L32: CAPEX subsidies are often generous, especially for replacing fossil systems w/ heat pumps. | N32: OPEX support is not formalized. EU ETS does not apply. | O32: 30 | P32: 80 | Q32: 8.0/5.6
A33: Germany (Frankfurt) | B33: Meat processing | C33: 1560 | D33: 50 | E33: 180 according to Eurostat, but a scheme is currently running (for five years only) | F33: 58 | G33: Prices in this column (excl UK) are from Eurostat, autumn 2024 | H33: 13 | I33: Prices in this column (excl UK) are from Eurostat, autumn 2024 | J33: =SUM(F33+H33) -> 71 | K33: 0.02 | L33: Max 21,000 euros per heat pump. | M33: 0 | O33: 30 | P33: 80 | Q33: 8.0/5.6
A34: UK/England (Newport) | B34: Processed food | C34: 15000 | D34: 140 | E34: As opposed to typical 215; classified as energy-intensive industries (EII) | F34: 78 | H34: 0 | I34: Carbon tax applies mainly to electricity generators | J34: =SUM(F34+H34) -> 78 | K34: 0.003 | L34: Limited. There is a £7,500 guaranteed grant per heat pump. | M34: 0 | N34: Other scheme: Climate Change Agreements (CCA) | O34: 55 (mix) | P34: 55 | Q34: 8.0/5.6
A35: The Netherlands (Agriport A7) | B35: Horticulture | C35: 1000 | D35: 100 | E35: As opposed to Eurostat's 117, for large industries | F35: 42 | H35: 20 | J35: =SUM(F35+H35) -> 62 | K35: 0.3 | L35: ISDE subsidy. | M35: 0 | O35: 55 | P35: 55 | Q35: 8.0/5.6 | R35: Proposed solution does not need heat pumps. The calculation is not supported properly.
A36: Spain (Zaragoza) | B36: Beer | C36: 3000 | D36: 90 | E36: As opposed to Eurostat's 98, for large industries | F36: 48 | H36: 4 | J36: =SUM(F36+H36) -> 52 | K36: 0.5 | L36: Funded via IDAE. Here: 35% for heat pump and another 15% for installation. | M36: 0 | N36: More schemes: The Interruptibility program; The Capacity market program | O36: 30 | P36: 80 | Q36: 8.0/5.6
A37: Sweden (Staffanstorp) | B37: Oat milk production | C37: 30000 | D37: 90 | E37: In Sweden’s SE4 bidding zone. Reasonable for a large industry (100 in Eurostat) | F37: 78 | H37: 31 | J37: =SUM(F37+H37) -> 109 | K37: 0.25 | L37: No fixed amount. Swedish Energy Agency grants, EU funding mechanisms | M37: 0 | O37: 30 | P37: 75 | Q37: 8.0/5.6 | R37: Sweden has no gas-powered industries, so the calculation is not supported properly.
A38: Natural gas costs are based on many sources, including:
A39: https://tradingeconomics.com/commodity/eu-natural-gas
A40: https://www.iea.org/reports/gas-market-report-q3-2025/executive-summary
A41: https://ec.europa.eu/eurostat/statistics-explained/images/d/d6/Statistic_Explained_figures_for_Gas_2024S2_v2.xlsx

Sheet Offtaker and Piping
F1: European average | I1: Click yellow field to view dropdown list
I2: =_xlfn.XLOOKUP(F1, Introduction!A:A, Introduction!R:R, 0)
A3: Offtaker System and Piping
A4: The system on this tab excludes DC costs (infrastructure) and savings (cooling) | F4: Distance (m) DC to Offtaker | H4: =_xlfn.XLOOKUP(F1, Introduction!A:A, Introduction!C:C, 0) -> 1000 | T4: This is NOT used in the calculation; just included for reference
A5: Delta-T is 12°C on the DC side. | F5: Distance in feet | H5: =SUM(H4*3.281) -> 3281 | I5: Note that changes to the values below
A6: Offtaker power need is 8 MW. Power from DC is 5.6 MW. | I6: will invalidate further dropdown changes. | T6: Temperature Loss Over Distance
A7: Assumes 8760 hour operation. | F7: Electricity price per MWh (€) | H7: =_xlfn.XLOOKUP(F1, Introduction!A:A, Introduction!D:D, 0) -> 150 | T7: Outgoing water temperature (30°C) from DC | W7: 30
F8: Natural gas price per MWh (€) | H8: =_xlfn.XLOOKUP(F1, Introduction!A:A, Introduction!F:F, 0) -> 54 | T8: Ambient temperature (typically 6-10 °C) | W8: 6
A9: Petter Terenius for DGA, July-August 2025 | F9: Carbon tax per MWh (€) | H9: =_xlfn.XLOOKUP(F1, Introduction!A:A, Introduction!H:H, 0) -> 12 | I9: =_xlfn.XLOOKUP(F1, Introduction!A:A, Introduction!I:I, 0) -> EU ETS only applies to industries over 20 MW; thus it does not pertain to the use cases. | T9: Heat loss (°C) | W9: =SUM(U25) -> 0.053543179
F10: CAPEX subsidy (%) | H10: =_xlfn.XLOOKUP(F1, Introduction!A:A, Introduction!K:K, 0) -> 0.3 | I10: =_xlfn.XLOOKUP(F1, Introduction!A:A, Introduction!L:L, 0) -> CAPEX subsidies are often generous, especially for replacing fossil systems w/ heat pumps.
F11: OPEX subsidy per ton avoided c. (€) | H11: =_xlfn.XLOOKUP(F1, Introduction!A:A, Introduction!M:M, 0) -> 0 | I11: =_xlfn.XLOOKUP(F1, Introduction!A:A, Introduction!N:N, 0) -> OPEX support is not formalized. EU ETS does not apply.
T12: Remaining heat (°C) | W12: =SUM(U26) -> 29.946457
A13: 30°C (86°F) scenario | F13: 65°C (150°F) scenario
A14: Water leaves DC at 30°C and returns at 18°C | F14: Water leaves DC at 65°C and returns at 53°C
A16: PIPING CAPEX | F16: PIPING CAPEX | K16: Comments | S16: Piping Heat Loss Calculator
A17: Cost Component | C17: Cost/Meter | D17: Estimated Cost (€) | F17: Cost Component | H17: Cost/Meter | I17: Estimated Cost (€) | S17: Water temperature from DC | U17: =SUM(W7) -> 30
A18: Insulated pipe (forward), 250 mm | C18: 120 | D18: =SUM(C18)*C24 -> 120000 | F18: Insulated pipe (forward), 250 mm | H18: 120 | I18: =SUM(H18)*H24 -> 120000 | K18: Insulated HDPE (SDR17) pipe forward; uninsulated same-size HDPE pipe return. Velocity rate: 2.3 m/s. | S18: Ambient temperature | U18: =SUM(W8) -> 6 | W18: Likely 6-10 degrees for buried pipe in Europe
A19: Uninsulated pipe (return), 250 mm | C19: 45 | D19: =SUM(C19)*C24 -> 45000 | F19: Uninsulated pipe (return), 250 mm | H19: 45 | I19: =SUM(H19)*H24 -> 45000 | K19: Dimensioning is a factor of heat needs, and affects pipe pricing. | S19: Difference water/ambient temp | U19: =SUM(U17-U18) -> 24 | W19: Pipe inner diameter D=0.1308 m
A20: Valves, fittings, sensors | C20: 10 | D20: =SUM(C20)*C24 -> 10000 | F20: Valves, fittings, sensors | H20: 10 | I20: =SUM(H20)*H24 -> 10000 | K20: Valves, fittings, sensors are €4000 per km | S20: U value for pipe | U20: 0.5 | W20: Insulation value. Varies a lot. U=x W/m²·K | Z20: https://www.isoplus.group/products/product-portfolio/details/product/isoflex-single-pipe/
A21: Installation and trenching | C21: 100 | D21: =SUM(C21)*C24 -> 100000 | F21: Installation | H21: 100 | I21: =SUM(H21)*H24 -> 100000 | K21: Trenching costs are heavily dependent on terrain and on hindering infrastructure. | S21: Qloss (W/m) | U21: =SUM(U20*3.1415*0.1308*U19) -> 4.9308984 | W21: Qloss = U*pi*D*deltaT
A22: Project management and design | C22: 50 | D22: =SUM(C22)*C24 -> 50000 | F22: Project management and design | H22: 50 | I22: =SUM(H22)*H24 -> 50000
A23: Pumps to keep pressure over distances (€5000/10 km) | D23: 5000 | F23: Pumps to keep pressure over distances (€5000 /10 km) | I23: 5000
A24: Distance (m) | C24: =SUM(H4) -> 1000 | F24: Distance (m) | H24: =SUM(H4) -> 1000 | K24: Note that at 65°C, steel pipes may be preferable for endurance. This would increase costs by up to 100%. | S24: Heat loss (°C/m) | U24: =SUM((U21)/(22*4186)) -> 5.3543179e-05 | W24: Flow rate = 22 kg/s
A25: Total | D25: =SUM(D18:D24) -> 330000 | F25: Total | I25: =SUM(I18:I24) -> 330000 | S25: Heat loss for installation (°C) | U25: =SUM(U24*H4) -> 0.053543179 | W25: deltaT = (Qloss)/(flow rate*water specific heat capacity)
S26: Remaining heat (°C) | U26: =SUM(U17-U25) -> 29.946457
A29: HEAT PUMP CAPEX per unit | F29: HEAT PUMP CAPEX
A30: Cost Component | C30: % of HP Cost | D30: Estimated Cost (€) | F30: Cost Component | H30: % of HP Cost | I30: Estimated Cost (€)
A31: 8 MW Heat Pump Unit | C31: n/a | D31: 2500000 | F31: 8 MW High-Temp Heat Pump Unit | H31: n/a | I31: 2500000 | K31: Instead of one 8 MW heat pump, it may be advisable to install 2*4 MW heat pumps.
A32: System Integration | C32: 0.2 | D32: =SUM(D31*C32) -> 500000 | F32: System Integration | H32: 0.2 | I32: =SUM(I31*H32) -> 500000 | K32: That would allow for partial load operation and for maintenance without full shutdown.
A33: Automation & Controls | C33: 0.2 | D33: =SUM(D31*C33) -> 500000 | F33: Automation & Controls | H33: 0.2 | I33: =SUM(I31*H33) -> 500000 | K33: The associated CAPEX increasee for that scenario is 10-20%.
A34: Refrigerants | C34: 0.05 | D34: =SUM(D31*C34) -> 125000 | F34: Refrigerants | H34: 0.05 | I34: =SUM(I31*H34) -> 125000
A35: Installation & Commissioning | C35: 0.5 | D35: =SUM(D31*C35) -> 1250000 | F35: Installation & Commissioning | H35: 0.5 | I35: =SUM(I31*H35) -> 1250000
A36: Total | D36: =SUM(D31:D35) -> 4875000 | F36: Total | I36: =SUM(I31:I35) -> 4875000
A40: STORAGE TANK CAPEX | F40: STORAGE TANK CAPEX
A41: Cost Component | C41: Notes | D41: Estimated Cost (€) | F41: Cost Component | H41: % of Tank Cost | I41: Estimated Cost (€)
A42: Tank, 100 m3, plus insulation | C42: Gives 30 mins | D42: 130000 | F42: Tank, 100 m3, plus insulation | H42: Gives 30 mins | I42: 130000 | K42: Needed to level out fluctuations due to differences in returning temperature from offtaker's processes.
A43: Controls, sensors, installation | C43: buffer at full heat | D43: 120000 | F43: Controls, sensors, installation | H43: buffer at full heat | I43: 120000
A44: Total | D44: =SUM(D42:D43) -> 250000 | F44: Total | I44: =SUM(I42:I43) -> 250000
A48: HEAT EXCHANGER CAPEX | F48: HEAT EXCHANGERS CAPEX
A49: Cost Component | C49: % of HX Cost | D49: Estimated Cost (€) | F49: Cost Component | H49: % of HX Cost | I49: Estimated Cost (€)
...

Sheet DC Economics
A2: Data Center Economics
A5: HEAT EXCHANGE ROOM CAPEX
A7: Cost Component | B7: Description | C7: Gain/Cost (€)
A8: HEAT REUSE CASE | C8: =SUM(C9:C20) -> 792000 | D8: Where there is exisiting infrastructure, this is the CAPEX.
A9: Plate heat exchanger | B9: Acts as a thermal bridge, transferring heat between loops | C9: 70000
A10: Primary pumps | B10: Circulate water through the datacenter loop | C10: 40000
A11: Secondary pumps | B11: Circulate water to the recipient loop | C11: 40000
A12: Control valves etc | B12: Regulate flow and temperature | C12: 15000
A13: Temp & flow sensors | B13: Monitor inlet/outlet temperatures and flow rates | C13: 6000
A14: Expansion tank | B14: Manages pressure changes in the closed loop | C14: 8000
A15: Water treatment | B15: Prevents corrosion and scaling in the loop | C15: 10000
A16: Piping | B16: Connects components within the room | C16: 40000
A17: Monitoring system | B17: Controls and monitors system performance | C17: 20000
A18: Safety measures | B18: Racks, mounts, drip trays, leak detection, fire safety | C18: 15000
A19: Redundancy material | B19: 50% of system cost | C19: {=SUM(C9:C18*0.5)} -> 132000
A20: Installation etc | B20: 100% of system cost (including redundancy materials) | C20: {=SUM(C9:C19*1)} -> 396000
A22: HEAT REJECTION CASE | B22: In other words, cost avoidance | C22: =SUM(C23:C29) -> 10450000 | D22: Where there will be no need to build heat rejection infrastructure, use this.
A23: Electric chillers (5.3 MW) | B23: High-efficiency chillers | C23: 3000000 | D23: Be careful with the minus sign, though!
A24: Cooling towers | B24: Rejects heat from condenser water loop | C24: 1500000
A25: Chilled water pumps, piping | B25: Circulates chilled water between chillers and air handlers | C25: 700000
A26: Condenser water pumps | B26: Circulates water between chillers and cooling towers | C26: 400000
A27: Control system | B27: Monitoring and optimization | C27: 350000
A28: Backup power system | B28: UPS + batteries or diesel gensets for cooling continuity | C28: 1500000
A29: Installation etc | B29: Labor, integration, testing | C29: 3000000
A31: Total CAPEX savings | C31: =SUM(C22-C8) -> 9658000 | D31: If no cooling infrastructure exists.
A33: Notes
A34: This calculation shows the difference between cooling and employing heat reuse for 5.6 MW in a data center.
A35: It does not factor in costs which would have been present in both cases, such as air coolers in server rooms.
A39: HEAT EXCHANGE ROOM OPEX COMPARISON
A41: Cost Component | B41: Comment | C41: Gain/Cost (€)
A42: HEAT REUSE CASE | C42: =SUM(C43:C46) -> 220000
A43: Electricity | C43: 120000 | D43: Pumps draw 100 kW.
A44: Maintenance | B44: Simpler components, fewer moving parts | C44: 60000
A45: Chemical treatment | C45: 15000
A46: Monitoring system | B46: Less complex automation in reuse system | C46: 25000 | D46: =SUM(C44:C46) -> 100000 | E46: Total excl power
A48: HEAT REJECTION CASE | B48: In other words, cost avoidance | C48: =SUM(C49:C53) -> 3170000
A49: Electricity | B49: Pumps only in reuse system | C49: 2500000 | D49: Power draw by chillers is approximately 2.0 MW.
A50: Maintenance | C50: 300000 | D50: Fans and pumps add another 350 kW.
A51: Water usage | B51: 70,000 m3 per year | C51: 220000 | D51: Power draw diff (MW): | E51: 2.2
A52: Chemical treatment | B52: Cooling towers require more aggressive treatment | C52: 50000
...

Sheet System Flow Diagrams
A2: System Flow Diagrams
