Workbook

Sheet Introduction
A2: Introduction
A4: This Excel document shows calculations for offtaker's heat reuse scenarios.
A5: Large offtakers in the F&B sector often operate at approximately 8 MW.
A6: Hence, that range is what these figures are adapted to.
A8: It should be noted that there is a major scaling factor in heat reuse, for piping, but also for offtaker's configuration and OPEX costs.
A9: In other words, should even bigger offtaker needs be identified, then that would decrease costs per MW.
A10: Also note that power costs vary substantially, so they need to be checked when estimating true project costs.
A12: For the identified use cases, the figures used are found in the table below. Greyed out cells are not used in the calculations.
A13: On the next tab, those numbers are used for the calculations, and a dropdown menu automatically inserts the values from the tables.
A15: The third tab hosts the system flow diagrams of the scenarios.
A17: Note that manual changes to the populated values will invalidate future dropdown changes (otherwise a VBA macro would be needed, which may conflict with safety protocol).
A18: So, please make a copy of this file to experiment with the figures, or re-insert them manually after changes, from the table below.
A20: Petter Terenius for DGA, August 2025
A23: Location | B23: F&B Facility Type | C23: Distance (m) | D23: 1 MWh Electricity (€) | F23: 1 MWh Natural gas (€) | H23: Carbon Tax (€) | I23: Carbon Tax Comment | J23: CAPEX Subsidies / Green Financing | K23: CAPEX Subsidies / Green Financing Comment | L23: OPEX subsidy / ton avoided carbon (€) | M23: OPEX subsidy… Comment | N23: DC Temp (°C) | O23: Offtaker Temp (°C) | P23: Heat need Total / Heat need DC (MW) | Q23: Payback period comment
A24: European average | B24: F&B industry | C24: 1000 | D24: 117 | E24: Electricity prices vary widely: must be investigated by actual case. | F24: 32 | G24: Cheaper per MWh, but carbon taxes and volatility make it less attractive. | H24: 57 | I24: In the EU, mainly EU ETS. | J24: 0.3 | K24: CAPEX subsidies are often generous, especially for replacing fossil systems w/ heat pumps. | M24: OPEX support is not formalized. | N24: 30 | O24: 80 | P24: 8.0/5.6
A25: Germany (Frankfurt) | B25: Meat processing | C25: 1560 | D25: 160 | F25: 80 | H25: 73 | I25: EU ETS | J25: 0.02 | K25: Max 21,000 euros per heat pump. | L25: 0 | M25: No direct operational subsidy. | N25: 30 | O25: 80 | P25: 8.0/5.6
A26: UK/England (Newport) | B26: Processed food | C26: 15000 | D26: 122 | F26: 81 | H26: 0 | I26: Carbon tax (22 euros/ton) applies mainly to electricity generators | J26: 0.003 | K26: Limited. There is a £7,500 guaranteed grant per heat pump. | L26: 0 | M26: No direct operational subsidy. | N26: 55 (mix) | O26: 55 | P26: 8.0/5.6
A27: The Netherlands (Agriport A7) | B27: Horticulture | C27: 1000 | D27: 152 | F27: 32 | H27: 74 | I27: Dutch national CO₂ levy, semi-aligned w/ EU ETS | J27: 0.3 | K27: ISDE subsidy. | L27: 0 | M27: No direct operational subsidy. | N27: 55 | O27: 55 | P27: 8.0/5.6 | Q27: Proposed solution does not need heat pumps. The calculation is not supported properly.
A28: Spain (Zaragoza) | B28: Beer | C28: 3000 | D28: 98 | F28: 33 | H28: 73 | I28: EU ETS | J28: 0.5 | K28: Funded via IDAE. Here: 35% for heat pump and another 15% for installation. | L28: 0 | M28: No direct operational subsidy. | N28: 30 | O28: 80 | P28: 8.0/5.6
A29: Sweden (Staffanstorp) | B29: Oat milk production | C29: 30000 | D29: 52 | E29: In Sweden’s SE3 bidding zone | F29: 113 | H29: 73 | I29: EU ETS. In principle zero, as gas is not used. | J29: 0.25 | K29: No fixed amount. Swedish Energy Agency grants, EU funding mechanisms | L29: 0 | M29: No direct operational subsidy. | N29: 30 | O29: 75 | P29: 8.0/5.6 | Q29: Sweden has no gas-powered industries, so the calculation is not supported properly.

Sheet Offtaker and Piping
F1: European average
F2: Payback period, 30°C (if applicable) | H2: =C139 -> 32.066905 | I2: =_xlfn.XLOOKUP(F1, Introduction!A:A, Introduction!Q:Q, 0)
A3: Offtaker System and Piping
A4: System excludes DC costs (infrastructure) and savings (cooling) | F4: Distance (m) DC to Offtaker | H4: 1000 | T4: This is NOT used in the calculation; just included for reference
A5: Delta-T is 12°C on the DC side. Offtaker power need is 8 MW. | F5: Distance in feet | H5: =SUM(H4*3.281) -> 3281 | I5: Note that changes to the values below
A6: Assumes 8760 hour operation. | I6: will invalidate further dropdown changes. | T6: Temperature Loss Over Distance
F7: Electricity price per MWh (€) | H7: =_xlfn.XLOOKUP(F1, Introduction!A:A, Introduction!D:D, 0) -> 117 | T7: Outgoing water temperature (30°C) from DC | W7: 30
A8: Petter Terenius for DGA, July-August 2025 | F8: Natural gas price per MWh (€) | H8: =_xlfn.XLOOKUP(F1, Introduction!A:A, Introduction!F:F, 0) -> 32 | T8: Ambient temperature (typically 6-10 °C) | W8: 6
F9: Carbon tax per ton (€) | H9: =_xlfn.XLOOKUP(F1, Introduction!A:A, Introduction!H:H, 0) -> 57 | I9: =_xlfn.XLOOKUP(F1, Introduction!A:A, Introduction!I:I, 0) -> In the EU, mainly EU ETS. | T9: Heat loss (°C) | W9: =SUM(U26) -> 0.053543179
F10: CAPEX subsidy (%) | H10: =_xlfn.XLOOKUP(F1, Introduction!A:A, Introduction!J:J, 0) -> 0.3 | I10: =_xlfn.XLOOKUP(F1, Introduction!A:A, Introduction!K:K, 0) -> CAPEX subsidies are often generous, especially for replacing fossil systems w/ heat pumps.
F11: OPEX subsidy per ton avoided c. (€) | H11: =_xlfn.XLOOKUP(F1, Introduction!A:A, Introduction!L:L, 0) -> 0 | I11: =_xlfn.XLOOKUP(F1, Introduction!A:A, Introduction!M:M, 0) -> OPEX support is not formalized.
T12: Remaining heat (°C) | W12: =SUM(U27) -> 29.946457
A13: 30°C (86°F) scenario | F13: 65°C (150°F) scenario
A14: Water leaves DC at 30°C and returns at 18°C | F14: Water leaves DC at 65°C and returns at 53°C
A16: PIPING CAPEX | F16: PIPING CAPEX | K16: Comments | S16: Piping Heat Loss Calculator
A17: Cost Component | C17: Cost/Meter | D17: Estimated Cost (€) | F17: Cost Component | H17: Cost/Meter | I17: Estimated Cost (€) | S17: Water temperature from DC | U17: =SUM(W7) -> 30
A18: Insulated pipe (forward), 160 mm | C18: 45 | D18: =SUM(C18)*C24 -> 45000 | F18: Insulated pipe (forward), 160 mm | H18: 45 | I18: =SUM(H18)*H24 -> 45000 | K18: Insulated HDPE (SDR11) pipe forward; uninsulated same-size HDPE pipe return. Velocity rate: 2.0 m/s. | S18: Ambient temperature | U18: =SUM(W8) -> 6 | W18: Likely 6-10 degrees for buried pipe in Europe
A19: Uninsulated pipe (return), 160 mm | C19: 22 | D19: =SUM(C19)*C24 -> 22000 | F19: Uninsulated pipe (return), 160 mm | H19: 22 | I19: =SUM(H19)*H24 -> 22000 | K19: Dimensioning is a factor of heat needs, and affects pipe pricing. | S19: Difference water/ambient temp | U19: =SUM(U17-U18) -> 24 | W19: Pipe inner diameter D=0.1308 m
A20: Valves, fittings, sensors | C20: 10 | D20: =SUM(C20)*C24 -> 10000 | F20: Valves, fittings, sensors | H20: 10 | I20: =SUM(H20)*H24 -> 10000 | K20: Valves, fittings, sensors are €4000 per km | S20: U value for pipe | U20: 0.5 | W20: Insulation value. Varies a lot. U=x W/m²·K | Z20: https://www.isoplus.group/products/product-portfolio/details/product/isoflex-single-pipe/
A21: Installation and trenching | C21: 100 | D21: =SUM(C21)*C24 -> 100000 | F21: Installation | H21: 100 | I21: =SUM(H21)*H24 -> 100000 | K21: Trenching costs are heavily dependent on terrain and on hindering infratructure. | S21: Qloss (W/m) | U21: =SUM(U20*3.1415*0.1308*U19) -> 4.9308984 | W21: Qloss = U*pi*D*deltaT
A22: Project management and design | C22: 50 | D22: =SUM(C22)*C24 -> 50000 | F22: Project management and design | H22: 50 | I22: =SUM(H22)*H24 -> 50000
A23: Pumps to keep pressure over distances (€5000/10 km) | D23: 5000 | F23: Pumps to keep pressure over distances (€5000 /10 km) | I23: 5000
A24: Distance (m) | C24: =SUM(H4) -> 1000 | F24: Distance (m) | H24: =SUM(H4) -> 1000 | K24: Note that at 65°C, steel pipes may be preferable for endurance. This would increase costs by up to 100%. | S24: Heat loss (°C/m) | U24: =SUM((U21)/(22*4186)) -> 5.3543179e-05 | W24: Flow rate = 22 kg/s
A25: Project management etc | D25: 40000 | F25: Project management etc | I25: 40000
A26: Total | D26: =SUM(D18:D25) -> 272000 | F26: Total | I26: =SUM(I18:I25) -> 272000 | S26: Heat loss for installation (°C) | U26: =SUM(U24*H4) -> 0.053543179 | W26: deltaT = (Qloss)/(flow rate*water specific heat capacity)
S27: Remaining heat (°C) | U27: =SUM(U17-U26) -> 29.946457
A30: HEAT PUMP CAPEX per unit | F30: HEAT PUMP CAPEX
A31: Cost Component | C31: % of HP Cost | D31: Estimated Cost (€) | F31: Cost Component | H31: % of HP Cost | I31: Estimated Cost (€)
A32: 8 MW Heat Pump Unit | C32: n/a | D32: 2200000 | F32: 8 MW High-Temp Heat Pump Unit | H32: n/a | I32: 2600000 | K32: These figures are rather volatile and must be discussed on a case-by-case basis.
A33: System Integration | C33: 0.2 | D33: =SUM(D32*C33) -> 440000 | F33: System Integration | H33: 0.2 | I33: =SUM(I32*H33) -> 520000 | K33: Here, they cost is moderate to high.
A34: Automation & Controls | C34: 0.2 | D34: =SUM(D32*C34) -> 440000 | F34: Automation & Controls | H34: 0.2 | I34: =SUM(I32*H34) -> 520000 | K34: Slightly higher price estimate for the 65 degree heat pump, due to untypically high inlet temperature.
A35: Installation & Commissioning | C35: 0.4 | D35: =SUM(D32*C35) -> 880000 | F35: Installation & Commissioning | H35: 0.4 | I35: =SUM(I32*H35) -> 1040000
A36: Total | D36: =SUM(D32:D35) -> 3960000 | F36: Total | I36: =SUM(I32:I35) -> 4680000
A40: STORAGE TANK CAPEX | F40: STORAGE TANK CAPEX
A41: Cost Component | C41: Notes | D41: Estimated Cost (€) | F41: Cost Component | H41: % of Tank Cost | I41: Estimated Cost (€)
A42: Tank, 100 m3, plus insulation | C42: Gives 30 mins | D42: 130000 | F42: Tank, 100 m3, plus insulation | H42: Gives 30 mins | I42: 130000 | K42: Needed to level out fluctuations due to differences in returning temperature from offtaker's processes.
A43: Controls, sensors, installation | C43: buffer at full heat | D43: 120000 | F43: Controls, sensors, installation | H43: buffer at full heat | I43: 120000
A44: Total | D44: =SUM(D42:D43) -> 250000 | F44: Total | I44: =SUM(I42:I43) -> 250000
A48: HEAT EXCHANGER CAPEX | F48: HEAT EXCHANGERS CAPEX
A49: Cost Component | C49: % of HX Cost | D49: Estimated Cost (€) | F49: Cost Component | H49: % of HX Cost | I49: Estimated Cost (€)
...

Sheet System Flow Diagrams
A2: System Flow Diagrams
